<?xml version="1.0"?>
<gazebo>
   <plugin name="differential_drive_controller" filename="libgazebo_ros_diff_drive.so">
       <alwaysOn>true</alwaysOn>
       <leftJoint>wheel_left_joint</leftJoint>
       <rightJoint>wheel_right_joint</rightJoint>
       <wheelSeparation>0.24</wheelSeparation>
       <wheelDiameter>0.2</wheelDiameter>
       <torque>10</torque>
       <commandTopic>cmd_vel</commandTopic>
       <odometryTopic>odom</odometryTopic>
       <odometryFrame>odom</odometryFrame>
       <robotBaseFrame>base_link</robotBaseFrame>
   </plugin>
</gazebo>


<robot name="car">
  <!-- 底盘 -->
  <link name="base_link">
    <visual>
      <geometry>
        <box size="0.4 0.2 0.05"/>
      </geometry>
      <material name="blue">
        <color rgba="0.2 0.2 0.8 1"/>
      </material>
    </visual>
    <collision>
      <geometry>
        <box size="0.4 0.2 0.05"/>
      </geometry>
    </collision>
    <inertial>
      <mass value="1"/>
      <origin rpy="0 0 0" xyz="0 0 0"/>
      <inertia ixx="0.001" ixy="0" ixz="0" iyy="0.001" iyz="0" izz="0.001"/>
    </inertial>
  </link>
  
  <!-- 左轮 -->
  <link name="wheel_left_link">
    <visual>
      <geometry>
        <cylinder length="0.03" radius="0.08"/>
      </geometry>
      <material name="gray">
        <color rgba="0.5 0.5 0.5 1"/>
      </material>
    </visual>
    <collision>
      <geometry>
        <cylinder length="0.03" radius="0.08"/>
      </geometry>
    </collision>
    <inertial>
      <mass value="0.1"/>
      <origin rpy="0 0 0" xyz="0 0 0"/>
      <inertia ixx="0.0001" ixy="0" ixz="0" iyy="0.0001" iyz="0" izz="0.0001"/>
    </inertial>
  </link>
  
  <!-- 右轮 -->
  <link name="wheel_right_link">
    <visual>
      <geometry>
        <cylinder length="0.03" radius="0.08"/>
      </geometry>
      <material name="gray">
        <color rgba="0.5 0.5 0.5 1"/>
      </material>
    </visual>
    <collision>
      <geometry>
        <cylinder length="0.03" radius="0.08"/>
      </geometry>
    </collision>
    <inertial>
      <mass value="0.1"/>
      <origin rpy="0 0 0" xyz="0 0 0"/>
      <inertia ixx="0.0001" ixy="0" ixz="0" iyy="0.0001" iyz="0" izz="0.0001"/>
    </inertial>
  </link>
  
  <!-- 万向轮 -->
  <link name="caster_link">
    <visual>
      <geometry>
        <sphere radius="0.05"/>
      </geometry>
      <material name="black">
        <color rgba="0 0 0 1"/>
      </material>
    </visual>
    <collision>
      <geometry>
        <sphere radius="0.05"/>
      </geometry>
    </collision>
    <inertial>
      <mass value="0.05"/>
      <origin rpy="0 0 0" xyz="0 0 0"/>
      <inertia ixx="0.00001" ixy="0" ixz="0" iyy="0.00001" iyz="0" izz="0.00001"/>
    </inertial>
  </link>
  
  <!-- 左轮关节（绕Y轴旋转） -->
  <joint name="wheel_left_joint" type="revolute">
    <parent link="base_link"/>
    <child link="wheel_left_link"/>
    <origin xyz="-0.15 0.1 0" rpy="1.5708 0 0"/>
    <axis xyz="0 1 0"/>
    <limit effort="100" lower="-1000" upper="1000" velocity="10"/>
  </joint>
  
  <!-- 右轮关节（绕Y轴旋转） -->
  <joint name="wheel_right_joint" type="revolute">
    <parent link="base_link"/>
    <child link="wheel_right_link"/>
    <origin xyz="-0.15 -0.1 0" rpy="1.5708 0 0"/>
    <axis xyz="0 1 0"/>
    <limit effort="100" lower="-1000" upper="1000" velocity="10"/>
  </joint>
  
  <!-- 万向轮关节（固定） -->
  <joint name="caster_joint" type="fixed">
    <parent link="base_link"/>
    <child link="caster_link"/>
    <origin xyz="0.15 0 -0.05"/>
  </joint>
</robot>
